2019-03-14 17:33:56,946 ERROR: Exception on /index [GET] [in /Users/zhangwei/Downloads/projects/microblog/venv/lib/python3.7/site-packages/flask/app.py:1761]
Traceback (most recent call last):
  File "/Users/zhangwei/Downloads/projects/microblog/venv/lib/python3.7/site-packages/flask/app.py", line 2292, in wsgi_app
    response = self.full_dispatch_request()
  File "/Users/zhangwei/Downloads/projects/microblog/venv/lib/python3.7/site-packages/flask/app.py", line 1815, in full_dispatch_request
    rv = self.handle_user_exception(e)
  File "/Users/zhangwei/Downloads/projects/microblog/venv/lib/python3.7/site-packages/flask/app.py", line 1718, in handle_user_exception
    reraise(exc_type, exc_value, tb)
  File "/Users/zhangwei/Downloads/projects/microblog/venv/lib/python3.7/site-packages/flask/_compat.py", line 35, in reraise
    raise value
  File "/Users/zhangwei/Downloads/projects/microblog/venv/lib/python3.7/site-packages/flask/app.py", line 1813, in full_dispatch_request
    rv = self.dispatch_request()
  File "/Users/zhangwei/Downloads/projects/microblog/venv/lib/python3.7/site-packages/flask/app.py", line 1799, in dispatch_request
    return self.view_functions[rule.endpoint](**req.view_args)
  File "/Users/zhangwei/Downloads/projects/microblog/app/routes.py", line 12, in index
    form = PostForm()
TypeError: PostForm() missing 1 required positional argument: 'FlaskForm'
2019-03-14 17:34:00,668 ERROR: Exception on /index [GET] [in /Users/zhangwei/Downloads/projects/microblog/venv/lib/python3.7/site-packages/flask/app.py:1761]
Traceback (most recent call last):
  File "/Users/zhangwei/Downloads/projects/microblog/venv/lib/python3.7/site-packages/flask/app.py", line 2292, in wsgi_app
    response = self.full_dispatch_request()
  File "/Users/zhangwei/Downloads/projects/microblog/venv/lib/python3.7/site-packages/flask/app.py", line 1815, in full_dispatch_request
    rv = self.handle_user_exception(e)
  File "/Users/zhangwei/Downloads/projects/microblog/venv/lib/python3.7/site-packages/flask/app.py", line 1718, in handle_user_exception
    reraise(exc_type, exc_value, tb)
  File "/Users/zhangwei/Downloads/projects/microblog/venv/lib/python3.7/site-packages/flask/_compat.py", line 35, in reraise
    raise value
  File "/Users/zhangwei/Downloads/projects/microblog/venv/lib/python3.7/site-packages/flask/app.py", line 1813, in full_dispatch_request
    rv = self.dispatch_request()
  File "/Users/zhangwei/Downloads/projects/microblog/venv/lib/python3.7/site-packages/flask/app.py", line 1799, in dispatch_request
    return self.view_functions[rule.endpoint](**req.view_args)
  File "/Users/zhangwei/Downloads/projects/microblog/app/routes.py", line 12, in index
    form = PostForm()
TypeError: PostForm() missing 1 required positional argument: 'FlaskForm'
2019-03-20 14:57:14,379 INFO: Microblog startup [in ./app/__init__.py:80]
2019-03-20 14:58:02,559 ERROR: Unhandled exception [in ./app/tasks.py:50]
Traceback (most recent call last):
  File "./app/tasks.py", line 47, in export_posts
    sync=True)
  File "./app/email.py", line 16, in send_email
    mail.send(msg)
  File "/Users/zhangwei/Downloads/projects/microblog/venv/lib/python3.7/site-packages/flask_mail.py", line 491, in send
    with self.connect() as connection:
  File "/Users/zhangwei/Downloads/projects/microblog/venv/lib/python3.7/site-packages/flask_mail.py", line 144, in __enter__
    self.host = self.configure_host()
  File "/Users/zhangwei/Downloads/projects/microblog/venv/lib/python3.7/site-packages/flask_mail.py", line 165, in configure_host
    host.login(self.mail.username, self.mail.password)
  File "/usr/local/Cellar/python/3.7.2_1/Frameworks/Python.framework/Versions/3.7/lib/python3.7/smtplib.py", line 730, in login
    raise last_exception
  File "/usr/local/Cellar/python/3.7.2_1/Frameworks/Python.framework/Versions/3.7/lib/python3.7/smtplib.py", line 721, in login
    initial_response_ok=initial_response_ok)
  File "/usr/local/Cellar/python/3.7.2_1/Frameworks/Python.framework/Versions/3.7/lib/python3.7/smtplib.py", line 642, in auth
    raise SMTPAuthenticationError(code, resp)
smtplib.SMTPAuthenticationError: (535, b'5.7.8 Username and Password not accepted. Learn more at\n5.7.8  https://support.google.com/mail/?p=BadCredentials n15sm3089718pgc.92 - gsmtp')
2019-03-26 16:14:23,064 INFO: Microblog startup [in ./app/__init__.py:52]
2019-03-26 16:17:22,027 ERROR: Unhandled exception [in ./app/tasks.py:50]
Traceback (most recent call last):
  File "./app/tasks.py", line 37, in export_posts
    time.sleep(5)
  File "/Users/zhangwei/Downloads/projects/microblog/venv/lib/python3.7/site-packages/rq/timeouts.py", line 64, in handle_death_penalty
    '({0} seconds)'.format(self._timeout))
rq.timeouts.JobTimeoutException: Task exceeded maximum timeout value (180 seconds)
2019-03-26 16:49:34,709 INFO: Microblog startup [in ./app/__init__.py:52]
2019-03-26 16:52:33,847 ERROR: Unhandled exception [in ./app/tasks.py:50]
Traceback (most recent call last):
  File "./app/tasks.py", line 37, in export_posts
    time.sleep(5)
  File "/Users/zhangwei/Downloads/projects/microblog/venv/lib/python3.7/site-packages/rq/timeouts.py", line 64, in handle_death_penalty
    '({0} seconds)'.format(self._timeout))
rq.timeouts.JobTimeoutException: Task exceeded maximum timeout value (180 seconds)
2019-03-26 17:03:39,665 INFO: Microblog startup [in ./app/__init__.py:52]
